<?xml version="1.0" encoding="UTF-8"?>
<testng-results skipped="0" failed="4" ignored="0" total="11" passed="7">
  <reporter-output>
  </reporter-output>
  <suite name="Suite" duration-ms="51" started-at="2018-03-11T03:32:16Z" finished-at="2018-03-11T03:32:16Z">
    <groups>
    </groups>
    <test name="Test" duration-ms="51" started-at="2018-03-11T03:32:16Z" finished-at="2018-03-11T03:32:16Z">
      <class name="com.harsha.javaPractice.collections.day12.HashTableExample">
        <test-method status="PASS" signature="hasTablePractice()[pri:0, instance:com.harsha.javaPractice.collections.day12.HashTableExample@573f2bb1]" name="hasTablePractice" duration-ms="9" started-at="2018-03-11T09:02:16Z" finished-at="2018-03-11T09:02:16Z">
          <reporter-output>
          </reporter-output>
        </test-method> <!-- hasTablePractice -->
      </class> <!-- com.harsha.javaPractice.collections.day12.HashTableExample -->
      <class name="com.harsha.javaPractice.Exceptions.day7.ExceptionHandling">
        <test-method status="PASS" signature="arrayIndexOutOfBoundExceptionPractice()[pri:0, instance:com.harsha.javaPractice.Exceptions.day7.ExceptionHandling@50c87b21]" name="arrayIndexOutOfBoundExceptionPractice" duration-ms="1" started-at="2018-03-11T09:02:16Z" finished-at="2018-03-11T09:02:16Z">
          <reporter-output>
          </reporter-output>
        </test-method> <!-- arrayIndexOutOfBoundExceptionPractice -->
        <test-method status="FAIL" signature="fileNotFoundExceptionHandlingPractice()[pri:0, instance:com.harsha.javaPractice.Exceptions.day7.ExceptionHandling@50c87b21]" name="fileNotFoundExceptionHandlingPractice" duration-ms="1" started-at="2018-03-11T09:02:16Z" finished-at="2018-03-11T09:02:16Z">
          <exception class="java.io.FileNotFoundException">
            <message>
              <![CDATA[G:/Eclipse/Workspace (No such file or directory)]]>
            </message>
            <full-stacktrace>
              <![CDATA[java.io.FileNotFoundException: G:/Eclipse/Workspace (No such file or directory)
	at java.io.FileInputStream.open0(Native Method)
	at java.io.FileInputStream.open(FileInputStream.java:195)
	at java.io.FileInputStream.<init>(FileInputStream.java:138)
	at java.io.FileReader.<init>(FileReader.java:72)
	at com.harsha.javaPractice.Exceptions.day7.ExceptionHandling.fileNotFoundExceptionHandlingPractice(ExceptionHandling.java:32)
	at sun.reflect.NativeMethodAccessorImpl.invoke0(Native Method)
	at sun.reflect.NativeMethodAccessorImpl.invoke(NativeMethodAccessorImpl.java:62)
	at sun.reflect.DelegatingMethodAccessorImpl.invoke(DelegatingMethodAccessorImpl.java:43)
	at java.lang.reflect.Method.invoke(Method.java:498)
	at org.testng.internal.MethodInvocationHelper.invokeMethod(MethodInvocationHelper.java:108)
	at org.testng.internal.Invoker.invokeMethod(Invoker.java:669)
	at org.testng.internal.Invoker.invokeTestMethod(Invoker.java:877)
	at org.testng.internal.Invoker.invokeTestMethods(Invoker.java:1201)
	at org.testng.internal.TestMethodWorker.invokeTestMethods(TestMethodWorker.java:125)
	at org.testng.internal.TestMethodWorker.run(TestMethodWorker.java:109)
	at org.testng.TestRunner.privateRun(TestRunner.java:776)
	at org.testng.TestRunner.run(TestRunner.java:634)
	at org.testng.SuiteRunner.runTest(SuiteRunner.java:425)
	at org.testng.SuiteRunner.runSequentially(SuiteRunner.java:420)
	at org.testng.SuiteRunner.privateRun(SuiteRunner.java:385)
	at org.testng.SuiteRunner.run(SuiteRunner.java:334)
	at org.testng.SuiteRunnerWorker.runSuite(SuiteRunnerWorker.java:52)
	at org.testng.SuiteRunnerWorker.run(SuiteRunnerWorker.java:86)
	at org.testng.TestNG.runSuitesSequentially(TestNG.java:1318)
	at org.testng.TestNG.runSuitesLocally(TestNG.java:1243)
	at org.testng.TestNG.runSuites(TestNG.java:1161)
	at org.testng.TestNG.run(TestNG.java:1129)
	at org.testng.remote.AbstractRemoteTestNG.run(AbstractRemoteTestNG.java:114)
	at org.testng.remote.RemoteTestNG.initAndRun(RemoteTestNG.java:251)
	at org.testng.remote.RemoteTestNG.main(RemoteTestNG.java:77)
]]>
            </full-stacktrace>
          </exception> <!-- java.io.FileNotFoundException -->
          <reporter-output>
          </reporter-output>
        </test-method> <!-- fileNotFoundExceptionHandlingPractice -->
        <test-method status="FAIL" signature="nullPointerExceptionPractice()[pri:0, instance:com.harsha.javaPractice.Exceptions.day7.ExceptionHandling@50c87b21]" name="nullPointerExceptionPractice" duration-ms="2" started-at="2018-03-11T09:02:16Z" finished-at="2018-03-11T09:02:16Z">
          <exception class="java.lang.NullPointerException">
            <full-stacktrace>
              <![CDATA[java.lang.NullPointerException
	at com.harsha.javaPractice.Exceptions.day7.ExceptionHandling.nullPointerExceptionPractice(ExceptionHandling.java:48)
	at sun.reflect.NativeMethodAccessorImpl.invoke0(Native Method)
	at sun.reflect.NativeMethodAccessorImpl.invoke(NativeMethodAccessorImpl.java:62)
	at sun.reflect.DelegatingMethodAccessorImpl.invoke(DelegatingMethodAccessorImpl.java:43)
	at java.lang.reflect.Method.invoke(Method.java:498)
	at org.testng.internal.MethodInvocationHelper.invokeMethod(MethodInvocationHelper.java:108)
	at org.testng.internal.Invoker.invokeMethod(Invoker.java:669)
	at org.testng.internal.Invoker.invokeTestMethod(Invoker.java:877)
	at org.testng.internal.Invoker.invokeTestMethods(Invoker.java:1201)
	at org.testng.internal.TestMethodWorker.invokeTestMethods(TestMethodWorker.java:125)
	at org.testng.internal.TestMethodWorker.run(TestMethodWorker.java:109)
	at org.testng.TestRunner.privateRun(TestRunner.java:776)
	at org.testng.TestRunner.run(TestRunner.java:634)
	at org.testng.SuiteRunner.runTest(SuiteRunner.java:425)
	at org.testng.SuiteRunner.runSequentially(SuiteRunner.java:420)
	at org.testng.SuiteRunner.privateRun(SuiteRunner.java:385)
	at org.testng.SuiteRunner.run(SuiteRunner.java:334)
	at org.testng.SuiteRunnerWorker.runSuite(SuiteRunnerWorker.java:52)
	at org.testng.SuiteRunnerWorker.run(SuiteRunnerWorker.java:86)
	at org.testng.TestNG.runSuitesSequentially(TestNG.java:1318)
	at org.testng.TestNG.runSuitesLocally(TestNG.java:1243)
	at org.testng.TestNG.runSuites(TestNG.java:1161)
	at org.testng.TestNG.run(TestNG.java:1129)
	at org.testng.remote.AbstractRemoteTestNG.run(AbstractRemoteTestNG.java:114)
	at org.testng.remote.RemoteTestNG.initAndRun(RemoteTestNG.java:251)
	at org.testng.remote.RemoteTestNG.main(RemoteTestNG.java:77)
]]>
            </full-stacktrace>
          </exception> <!-- java.lang.NullPointerException -->
          <reporter-output>
          </reporter-output>
        </test-method> <!-- nullPointerExceptionPractice -->
        <test-method status="FAIL" signature="throwNewExceptionPractice()[pri:0, instance:com.harsha.javaPractice.Exceptions.day7.ExceptionHandling@50c87b21]" name="throwNewExceptionPractice" duration-ms="1" started-at="2018-03-11T09:02:16Z" finished-at="2018-03-11T09:02:16Z">
          <exception class="java.lang.Exception">
            <message>
              <![CDATA[This is my exception and its been designed by me !!!!]]>
            </message>
            <full-stacktrace>
              <![CDATA[java.lang.Exception: This is my exception and its been designed by me !!!!
	at com.harsha.javaPractice.Exceptions.day7.ExceptionHandling.throwNewExceptionPractice(ExceptionHandling.java:66)
	at sun.reflect.NativeMethodAccessorImpl.invoke0(Native Method)
	at sun.reflect.NativeMethodAccessorImpl.invoke(NativeMethodAccessorImpl.java:62)
	at sun.reflect.DelegatingMethodAccessorImpl.invoke(DelegatingMethodAccessorImpl.java:43)
	at java.lang.reflect.Method.invoke(Method.java:498)
	at org.testng.internal.MethodInvocationHelper.invokeMethod(MethodInvocationHelper.java:108)
	at org.testng.internal.Invoker.invokeMethod(Invoker.java:669)
	at org.testng.internal.Invoker.invokeTestMethod(Invoker.java:877)
	at org.testng.internal.Invoker.invokeTestMethods(Invoker.java:1201)
	at org.testng.internal.TestMethodWorker.invokeTestMethods(TestMethodWorker.java:125)
	at org.testng.internal.TestMethodWorker.run(TestMethodWorker.java:109)
	at org.testng.TestRunner.privateRun(TestRunner.java:776)
	at org.testng.TestRunner.run(TestRunner.java:634)
	at org.testng.SuiteRunner.runTest(SuiteRunner.java:425)
	at org.testng.SuiteRunner.runSequentially(SuiteRunner.java:420)
	at org.testng.SuiteRunner.privateRun(SuiteRunner.java:385)
	at org.testng.SuiteRunner.run(SuiteRunner.java:334)
	at org.testng.SuiteRunnerWorker.runSuite(SuiteRunnerWorker.java:52)
	at org.testng.SuiteRunnerWorker.run(SuiteRunnerWorker.java:86)
	at org.testng.TestNG.runSuitesSequentially(TestNG.java:1318)
	at org.testng.TestNG.runSuitesLocally(TestNG.java:1243)
	at org.testng.TestNG.runSuites(TestNG.java:1161)
	at org.testng.TestNG.run(TestNG.java:1129)
	at org.testng.remote.AbstractRemoteTestNG.run(AbstractRemoteTestNG.java:114)
	at org.testng.remote.RemoteTestNG.initAndRun(RemoteTestNG.java:251)
	at org.testng.remote.RemoteTestNG.main(RemoteTestNG.java:77)
]]>
            </full-stacktrace>
          </exception> <!-- java.lang.Exception -->
          <reporter-output>
          </reporter-output>
        </test-method> <!-- throwNewExceptionPractice -->
        <test-method status="PASS" signature="tryCatchBlockExample()[pri:0, instance:com.harsha.javaPractice.Exceptions.day7.ExceptionHandling@50c87b21]" name="tryCatchBlockExample" duration-ms="0" started-at="2018-03-11T09:02:16Z" finished-at="2018-03-11T09:02:16Z">
          <reporter-output>
          </reporter-output>
        </test-method> <!-- tryCatchBlockExample -->
        <test-method status="FAIL" signature="tryCatchExceptionPractice()[pri:0, instance:com.harsha.javaPractice.Exceptions.day7.ExceptionHandling@50c87b21]" name="tryCatchExceptionPractice" duration-ms="0" started-at="2018-03-11T09:02:16Z" finished-at="2018-03-11T09:02:16Z">
          <exception class="java.lang.Exception">
            <message>
              <![CDATA[This is my exception and its been designed by me !!!!]]>
            </message>
            <full-stacktrace>
              <![CDATA[java.lang.Exception: This is my exception and its been designed by me !!!!
	at com.harsha.javaPractice.Exceptions.day7.ExceptionHandling.tryCatchExceptionPractice(ExceptionHandling.java:78)
	at sun.reflect.NativeMethodAccessorImpl.invoke0(Native Method)
	at sun.reflect.NativeMethodAccessorImpl.invoke(NativeMethodAccessorImpl.java:62)
	at sun.reflect.DelegatingMethodAccessorImpl.invoke(DelegatingMethodAccessorImpl.java:43)
	at java.lang.reflect.Method.invoke(Method.java:498)
	at org.testng.internal.MethodInvocationHelper.invokeMethod(MethodInvocationHelper.java:108)
	at org.testng.internal.Invoker.invokeMethod(Invoker.java:669)
	at org.testng.internal.Invoker.invokeTestMethod(Invoker.java:877)
	at org.testng.internal.Invoker.invokeTestMethods(Invoker.java:1201)
	at org.testng.internal.TestMethodWorker.invokeTestMethods(TestMethodWorker.java:125)
	at org.testng.internal.TestMethodWorker.run(TestMethodWorker.java:109)
	at org.testng.TestRunner.privateRun(TestRunner.java:776)
	at org.testng.TestRunner.run(TestRunner.java:634)
	at org.testng.SuiteRunner.runTest(SuiteRunner.java:425)
	at org.testng.SuiteRunner.runSequentially(SuiteRunner.java:420)
	at org.testng.SuiteRunner.privateRun(SuiteRunner.java:385)
	at org.testng.SuiteRunner.run(SuiteRunner.java:334)
	at org.testng.SuiteRunnerWorker.runSuite(SuiteRunnerWorker.java:52)
	at org.testng.SuiteRunnerWorker.run(SuiteRunnerWorker.java:86)
	at org.testng.TestNG.runSuitesSequentially(TestNG.java:1318)
	at org.testng.TestNG.runSuitesLocally(TestNG.java:1243)
	at org.testng.TestNG.runSuites(TestNG.java:1161)
	at org.testng.TestNG.run(TestNG.java:1129)
	at org.testng.remote.AbstractRemoteTestNG.run(AbstractRemoteTestNG.java:114)
	at org.testng.remote.RemoteTestNG.initAndRun(RemoteTestNG.java:251)
	at org.testng.remote.RemoteTestNG.main(RemoteTestNG.java:77)
]]>
            </full-stacktrace>
          </exception> <!-- java.lang.Exception -->
          <reporter-output>
          </reporter-output>
        </test-method> <!-- tryCatchExceptionPractice -->
        <test-method status="PASS" signature="tryCatchFinallyBlockPractice()[pri:0, instance:com.harsha.javaPractice.Exceptions.day7.ExceptionHandling@50c87b21]" name="tryCatchFinallyBlockPractice" duration-ms="1" started-at="2018-03-11T09:02:16Z" finished-at="2018-03-11T09:02:16Z">
          <reporter-output>
          </reporter-output>
        </test-method> <!-- tryCatchFinallyBlockPractice -->
      </class> <!-- com.harsha.javaPractice.Exceptions.day7.ExceptionHandling -->
      <class name="com.harsha.javaPractice.collections.day12.StackExample">
        <test-method status="PASS" signature="stackPractice()[pri:0, instance:com.harsha.javaPractice.collections.day12.StackExample@6d78f375]" name="stackPractice" duration-ms="1" started-at="2018-03-11T09:02:16Z" finished-at="2018-03-11T09:02:16Z">
          <reporter-output>
          </reporter-output>
        </test-method> <!-- stackPractice -->
      </class> <!-- com.harsha.javaPractice.collections.day12.StackExample -->
      <class name="com.harsha.javaPractice.collections.day12.IteratorPractice">
        <test-method status="PASS" signature="iteratorPractice()[pri:0, instance:com.harsha.javaPractice.collections.day12.IteratorPractice@7ac7a4e4]" name="iteratorPractice" duration-ms="1" started-at="2018-03-11T09:02:16Z" finished-at="2018-03-11T09:02:16Z">
          <reporter-output>
          </reporter-output>
        </test-method> <!-- iteratorPractice -->
      </class> <!-- com.harsha.javaPractice.collections.day12.IteratorPractice -->
      <class name="com.harsha.javaPractice.collections.day12.ArrayListPractice">
        <test-method status="PASS" signature="arrayListExample()[pri:0, instance:com.harsha.javaPractice.collections.day12.ArrayListPractice@548b7f67]" name="arrayListExample" duration-ms="1" started-at="2018-03-11T09:02:16Z" finished-at="2018-03-11T09:02:16Z">
          <reporter-output>
          </reporter-output>
        </test-method> <!-- arrayListExample -->
      </class> <!-- com.harsha.javaPractice.collections.day12.ArrayListPractice -->
    </test> <!-- Test -->
  </suite> <!-- Suite -->
</testng-results>
